Workbook

Sheet Matriz
A1: SIRAM · Comparación de campos entre formularios de denuncia
A2: F1 = Formulario público (Schiavini) · F2 = Ventanilla Zoonosis Ushuaia (O.M. 4800) · F3 = pendiente. Estado: Sí / Parcial / Implícito / No. Columnas amarillas: completar cuando llegue el F3.
A4: Campo unificado | D4: F1 · Formulario público (Schiavini) | F4: F2 · Ventanilla Zoonosis Ushuaia | H4: F3 · (pendiente) | J4: Análisis
A5: Cód. | B5: Bloque | C5: Campo | D5: Estado | E5: Pregunta y opciones (textual) | F5: Estado | G5: Pregunta y opciones (textual) | H5: Estado | I5: Pregunta y opciones (textual) | J5: Presente en (n.º form.) | K5: Uso en SIRAM (Entrevista 1) | L5: Diferencias y notas de normalización
A6: P1 | B6: Persona | C6: Nombre y apellido | D6: Sí | E6: Nombre y apellido (texto) | F6: Sí | G6: Apellido y nombre (del denunciante) | J6: =OR(D6="Sí",D6="Parcial",D6="Implícito")*1+OR(F6="Sí",F6="Parcial",F6="Implícito")*1+OR(H6="Sí",H6="Parcial",H6="Implícito")*1 -> 2 | L6: F2 pide apellido primero; normalizar a un solo formato.
A7: P2 | B7: Persona | C7: Edad | D7: Sí | E7: Edad (texto) | F7: Sí | G7: Edad (del denunciante; la del lesionado va en P9) | J7: =OR(D7="Sí",D7="Parcial",D7="Implícito")*1+OR(F7="Sí",F7="Parcial",F7="Implícito")*1+OR(H7="Sí",H7="Parcial",H7="Implícito")*1 -> 2 | K7: Epidemiológico: edad
A8: P3 | B8: Persona | C8: Correo electrónico | D8: Sí | E8: Correo electrónico de contacto (texto) | F8: No | G8: — | J8: =OR(D8="Sí",D8="Parcial",D8="Implícito")*1+OR(F8="Sí",F8="Parcial",F8="Implícito")*1+OR(H8="Sí",H8="Parcial",H8="Implícito")*1 -> 1 | K8: Duplicados: complemento | L8: Solo F1.
A9: P4 | B9: Persona | C9: Teléfono | D9: Sí | E9: Teléfono de contacto (texto) | F9: Sí | G9: Teléfono de contacto (del denunciante) | J9: =OR(D9="Sí",D9="Parcial",D9="Implícito")*1+OR(F9="Sí",F9="Parcial",F9="Implícito")*1+OR(H9="Sí",H9="Parcial",H9="Implícito")*1 -> 2 | K9: Duplicados: complemento (celular)
A10: P5 | B10: Persona | C10: Tarea si trabaja en la calle | D10: Sí | E10: Si usted trabaja en la calle, indique su tarea: Cartero / Recolector de residuos / Inspector de tránsito / Notificador (de justicia o de juzgado de faltas) / Trabajador de servicios (Luz, Agua, Gas, etc.) / Otros | F10: No | G10: — | J10: =OR(D10="Sí",D10="Parcial",D10="Implícito")*1+OR(F10="Sí",F10="Parcial",F10="Implícito")*1+OR(H10="Sí",H10="Parcial",H10="Implícito")*1 -> 1 | L10: Solo F1. Contexto laboral de la persona agredida.
A11: P6 | B11: Persona | C11: DNI | D11: No | E11: — | F11: Sí | G11: D.N.I. N° (del denunciante) | J11: =OR(D11="Sí",D11="Parcial",D11="Implícito")*1+OR(F11="Sí",F11="Parcial",F11="Implícito")*1+OR(H11="Sí",H11="Parcial",H11="Implícito")*1 -> 1 | K11: Duplicados: clave principal | L11: Falta en F1 (ver HZ01).
A12: P7 | B12: Persona | C12: Domicilio de la persona | D12: No | E12: — | F12: Sí | G12: Domicilio (del denunciante) | J12: =OR(D12="Sí",D12="Parcial",D12="Implícito")*1+OR(F12="Sí",F12="Parcial",F12="Implícito")*1+OR(H12="Sí",H12="Parcial",H12="Implícito")*1 -> 1 | L12: Es el domicilio de la persona, no el lugar del hecho.
A13: P8 | B13: Persona | C13: Carácter del denunciante | D13: No | E13: — | F13: Sí | G13: En carácter de: (texto libre) | J13: =OR(D13="Sí",D13="Parcial",D13="Implícito")*1+OR(F13="Sí",F13="Parcial",F13="Implícito")*1+OR(H13="Sí",H13="Parcial",H13="Implícito")*1 -> 1 | L13: Texto libre, sin lista de valores.
A14: P9 | B14: Persona | C14: Datos del lesionado si no es el denunciante | D14: No | E14: — | F14: Sí | G14: Datos del lesionado (en caso de no ser el denunciante): Apellido y nombre, D.N.I., Edad, Teléfono, Domicilio | J14: =OR(D14="Sí",D14="Parcial",D14="Implícito")*1+OR(F14="Sí",F14="Parcial",F14="Implícito")*1+OR(H14="Sí",H14="Parcial",H14="Implícito")*1 -> 1 | L14: F1 asume que responde la persona agredida (inferido). Ver HZ07.
A15: H0 | B15: Hecho | C15: Fecha de la denuncia | D15: No | E15: — | F15: Sí | G15: Encabezado: Ushuaia, __ de __ de 20__ | J15: =OR(D15="Sí",D15="Parcial",D15="Implícito")*1+OR(F15="Sí",F15="Parcial",F15="Implícito")*1+OR(H15="Sí",H15="Parcial",H15="Implícito")*1 -> 1 | L15: F1: la planilla de respuestas de un formulario online suele guardar una marca temporal automática (inferido; verificar con el export real). Ver HZ14.
A16: H1 | B16: Hecho | C16: Fecha de la agresión | D16: Sí | E16: Fecha y hora de la agresión — Fecha (Día / Mes / Año) | F16: Sí | G16: Fecha de la agresión: __/__/__ | J16: =OR(D16="Sí",D16="Parcial",D16="Implícito")*1+OR(F16="Sí",F16="Parcial",F16="Implícito")*1+OR(H16="Sí",H16="Parcial",H16="Implícito")*1 -> 2 | K16: Obligatorio: cuándo · Duplicados: complemento (fecha)
A17: H2 | B17: Hecho | C17: Hora de la agresión | D17: Sí | E17: Hora (formato 24 h, HH:MM) | F17: Sí | G17: Hora: __:__ | J17: =OR(D17="Sí",D17="Parcial",D17="Implícito")*1+OR(F17="Sí",F17="Parcial",F17="Implícito")*1+OR(H17="Sí",H17="Parcial",H17="Implícito")*1 -> 2
A18: H3 | B18: Hecho | C18: Ciudad del hecho | D18: Sí | E18: Ciudad * : Río Grande / Tolhuin / Ushuaia / Otros | F18: Implícito | G18: No se pregunta; el encabezado dice «Ushuaia» (lugar de la denuncia) | J18: =OR(D18="Sí",D18="Parcial",D18="Implícito")*1+OR(F18="Sí",F18="Parcial",F18="Implícito")*1+OR(H18="Sí",H18="Parcial",H18="Implícito")*1 -> 2 | K18: Obligatorio: dónde | L18: F1: único campo marcado obligatorio. F2: se asume Ushuaia (inferido; validar). Ver HZ15.
A19: H4 | B19: Hecho | C19: Lugar / dirección del hecho | D19: Sí | E19: Lugar (calles) donde se produjo la agresión — calle, dirección o altura (ej. Maipú al 100) y ciudad | F19: Sí | G19: Lugar – Calle: ____ Nº ____ | J19: =OR(D19="Sí",D19="Parcial",D19="Implícito")*1+OR(F19="Sí",F19="Parcial",F19="Implícito")*1+OR(H19="Sí",H19="Parcial",H19="Implícito")*1 -> 2 | K19: Obligatorio: dónde | L19: F1 texto libre; F2 calle y número separados. Relevante para georreferenciar (mapa).
A20: H5 | B20: Hecho | C20: Tipo de lugar | D20: Sí | E20: Casa propia / Casa ajena / Zona Rural / Vía Pública / Espacio Público (plaza por ej.) | F20: Sí | G20: Casa propia / Casa ajena / Vía pública / Espacio público | J20: =OR(D20="Sí",D20="Parcial",D20="Implícito")*1+OR(F20="Sí",F20="Parcial",F20="Implícito")*1+OR(H20="Sí",H20="Parcial",H20="Implícito")*1 -> 2 | K20: Epidemiológico: ámbito (mapeo inferido) | L20: F2 no tiene «Zona rural».
A21: H6 | B21: Hecho | C21: Con quién estaba | D21: Sí | E21: ¿Con quién estaba en ese momento?: Solo / Acompañado | F21: Sí | G21: Con quién estaba en ese momento: Solo/a / Padre / Madre / Amigos / Otros | J21: =OR(D21="Sí",D21="Parcial",D21="Implícito")*1+OR(F21="Sí",F21="Parcial",F21="Implícito")*1+OR(H21="Sí",H21="Parcial",H21="Implícito")*1 -> 2 | K21: Obligatorio: situación de la persona (mapeo inferido) | L21: Granularidad distinta. F2 → F1 se puede mapear (Padre/Madre/Amigos/Otros = Acompañado); F1 → F2 no.
A22: H7 | B22: Hecho | C22: Iba acompañado por perros | D22: Sí | E22: Al momento de la mordedura, ¿usted iba acompañado por uno o más perros?: Sí / No | F22: No | G22: — | J22: =OR(D22="Sí",D22="Parcial",D22="Implícito")*1+OR(F22="Sí",F22="Parcial",F22="Implícito")*1+OR(H22="Sí",H22="Parcial",H22="Implícito")*1 -> 1 | L22: Solo F1.
A23: H8 | B23: Hecho | C23: Actividad al momento del ataque | D23: Sí | E23: ¿Qué estaba haciendo usted al momento del ataque?: Parado / Caminando / Sentado / Corriendo / Andando en bicicleta / Andando en moto / Interactuando con el animal | F23: No | G23: — | J23: =OR(D23="Sí",D23="Parcial",D23="Implícito")*1+OR(F23="Sí",F23="Parcial",F23="Implícito")*1+OR(H23="Sí",H23="Parcial",H23="Implícito")*1 -> 1 | K23: Obligatorio: situación de la persona (mapeo inferido) | L23: Solo F1. Ver HZ11.
A24: H9 | B24: Hecho | C24: Tipo de interacción con el animal | D24: Sí | E24: Si estaba interactuando con el animal, ¿cómo fue?: Lo estaba tocando / Lo estaba tocando mientras comía / Lo asistía porque había sido atropellado / Lo asistía porque había sido atacado por otro animal / Otros | F24: No | G24: — | J24: =OR(D24="Sí",D24="Parcial",D24="Implícito")*1+OR(F24="Sí",F24="Parcial",F24="Implícito")*1+OR(H24="Sí",H24="Parcial",H24="Implícito")*1 -> 1 | L24: Solo F1. Condicional a H8 = Interactuando.
A25: H10 | B25: Hecho | C25: Otros datos / testigos / observaciones | D25: Sí | E25: Otros datos que quiera aportar (testigos u otros elementos de prueba) (texto) | F25: Sí | G25: Observaciones / otros datos (texto libre) | J25: =OR(D25="Sí",D25="Parcial",D25="Implícito")*1+OR(F25="Sí",F25="Parcial",F25="Implícito")*1+OR(H25="Sí",H25="Parcial",H25="Implícito")*1 -> 2 | L25: F2 tiene un único campo libre.
A26: H11 | B26: Hecho | C26: Conoce al propietario del domicilio | D26: No | E26: — | F26: Sí | G26: Conoce al propietario/a del domicilio: SI / NO | J26: =OR(D26="Sí",D26="Parcial",D26="Implícito")*1+OR(F26="Sí",F26="Parcial",F26="Implícito")*1+OR(H26="Sí",H26="Parcial",H26="Implícito")*1 -> 1 | L26: Ambiguo: ¿domicilio del hecho o del animal? Pendiente (HZ16).
A27: T1 | B27: Tipo de evento | C27: Tipo de denuncia / evento | D27: No | E27: — | F27: Sí | G27: Tipo de denuncia: Mordedura de ADC / Lesión compatible con ataque de ADC / Canes sueltos, agresivos / Ataque de ADC a otro ADC / Mal estado de ADC / Otros | J27: =OR(D27="Sí",D27="Parcial",D27="Implícito")*1+OR(F27="Sí",F27="Parcial",F27="Implícito")*1+OR(H27="Sí",H27="Parcial",H27="Implícito")*1 -> 1 | K27: Tipificación del evento (RF.19) | L27: F1 cubre solo agresiones a personas (ver L1). Varias opciones del F2 quedan fuera de alcance (HZ03).
A28: X1 | B28: Documentación y trámite | C28: Adjunta certificado médico | D28: No | E28: — | F28: Sí | G28: Adjunta copia de certificado médico por mordedura de ADC o por lesión compatible con ataque de ADC: SI / NO | J28: =OR(D28="Sí",D28="Parcial",D28="Implícito")*1+OR(F28="Sí",F28="Parcial",F28="Implícito")*1+OR(H28="Sí",H28="Parcial",H28="Implícito")*1 -> 1 | L28: Plazo de 48 h hábiles para presentarlo; si no, la denuncia se desglosa y se devuelve (HZ08).
A29: X2 | B29: Documentación y trámite | C29: Adjunta fotos | D29: No | E29: — | F29: Sí | G29: Adjunta registro fotográfico del ADC involucrado o del lugar del hecho: SI / NO | J29: =OR(D29="Sí",D29="Parcial",D29="Implícito")*1+OR(F29="Sí",F29="Parcial",F29="Implícito")*1+OR(H29="Sí",H29="Parcial",H29="Implícito")*1 -> 1 | K29: Fotos (RF.25) | L29: F1 solo menciona «elementos de prueba» en texto libre (H10).
A30: X3 | B30: Documentación y trámite | C30: Firma y ratificación del denunciante | D30: No | E30: — | F30: Sí | G30: Firma y aclaración del denunciante; notificación del plazo; «Ratifico en todos sus términos» con segunda firma | J30: =OR(D30="Sí",D30="Parcial",D30="Implícito")*1+OR(F30="Sí",F30="Parcial",F30="Implícito")*1+OR(H30="Sí",H30="Parcial",H30="Implícito")*1 -> 1 | L30: Dato administrativo del trámite en papel.
A31: A1 | B31: Animal | C31: Especie | D31: Sí | E31: Animal causante de la lesión: Perro / Gato | F31: Sí | G31: Perro/a / Gato/a | J31: =OR(D31="Sí",D31="Parcial",D31="Implícito")*1+OR(F31="Sí",F31="Parcial",F31="Implícito")*1+OR(H31="Sí",H31="Parcial",H31="Implícito")*1 -> 2 | L31: Ambos incluyen gatos; gatos dentro del alcance: sin definir (HZ06).
A32: A2 | B32: Animal | C32: Tamaño | D32: Sí | E32: En caso de ser un perro, ¿qué tamaño tenía?: Grande (Mastín, Pastor Inglés, Pastor Alemán) / Mediano (Labrador, Pitbull, Border Collie) / Chico (Caniche, Schnauzer, Beagle) | F32: Sí | G32: Tamaño del ADC: Pequeño / Mediano / Grande | J32: =OR(D32="Sí",D32="Parcial",D32="Implícito")*1+OR(F32="Sí",F32="Parcial",F32="Implícito")*1+OR(H32="Sí",H32="Parcial",H32="Implícito")*1 -> 2 | K32: Filtro del mapa (tamaño) | L32: «Chico» (F1) = «Pequeño» (F2). F1 da ejemplos de razas y lo pregunta solo para perros.
A33: A3 | B33: Animal | C33: ¿Conoce la raza? | D33: Sí | E33: ¿Conoce su raza?: Sí / No | F33: Sí | G33: Conoce su raza: SI / NO / NO SÉ | J33: =OR(D33="Sí",D33="Parcial",D33="Implícito")*1+OR(F33="Sí",F33="Parcial",F33="Implícito")*1+OR(H33="Sí",H33="Parcial",H33="Implícito")*1 -> 2 | L33: F2 agrega «NO SÉ».
A34: A4 | B34: Animal | C34: Raza | D34: Sí | E34: Si sabe la raza, describirla (texto) | F34: Sí | G34: ¿Cuál es? (texto) | J34: =OR(D34="Sí",D34="Parcial",D34="Implícito")*1+OR(F34="Sí",F34="Parcial",F34="Implícito")*1+OR(H34="Sí",H34="Parcial",H34="Implícito")*1 -> 2
A35: A5 | B35: Animal | C35: Origen del animal | D35: Sí | E35: Origen del animal: Mascota propia / Ajeno conocido / Ajeno desconocido | F35: Sí | G35: Origen: Mascota propia / Ajeno conocido / Ajeno desconocido | J35: =OR(D35="Sí",D35="Parcial",D35="Implícito")*1+OR(F35="Sí",F35="Parcial",F35="Implícito")*1+OR(H35="Sí",H35="Parcial",H35="Implícito")*1 -> 2 | K35: Obligatorio: propio / ajeno | L35: Mismas opciones.
A36: A6 | B36: Animal | C36: ¿El dueño se responsabilizó? | D36: Sí | E36: Si el perro era ajeno, ¿el dueño se responsabilizó o colaboró? (texto) | F36: No | G36: — | J36: =OR(D36="Sí",D36="Parcial",D36="Implícito")*1+OR(F36="Sí",F36="Parcial",F36="Implícito")*1+OR(H36="Sí",H36="Parcial",H36="Implícito")*1 -> 1 | L36: Solo F1.
A37: A7 | B37: Animal | C37: Domicilio o zona del animal | D37: Sí | E37: Si conoce el domicilio del animal agresor, indíquelo (ej. Maipú al 100) | F37: Sí | G37: Dirección o zona del animal agresor | J37: =OR(D37="Sí",D37="Parcial",D37="Implícito")*1+OR(F37="Sí",F37="Parcial",F37="Implícito")*1+OR(H37="Sí",H37="Parcial",H37="Implícito")*1 -> 2 | L37: Mismo dato.
A38: A8 | B38: Animal | C38: Vacuna antirrábica del animal | D38: Sí | E38: ¿Sabe si el animal está vacunado contra la Rabia?: Si / No / No sabe | F38: No | G38: — | J38: =OR(D38="Sí",D38="Parcial",D38="Implícito")*1+OR(F38="Sí",F38="Parcial",F38="Implícito")*1+OR(H38="Sí",H38="Parcial",H38="Implícito")*1 -> 1 | L38: Solo F1.
A39: A9 | B39: Animal | C39: Sexo del animal | D39: Sí | E39: Sexo: Macho / Hembra / No sabe | F39: Sí | G39: Sexo: Macho / Hembra | J39: =OR(D39="Sí",D39="Parcial",D39="Implícito")*1+OR(F39="Sí",F39="Parcial",F39="Implícito")*1+OR(H39="Sí",H39="Parcial",H39="Implícito")*1 -> 2 | L39: F2 no tiene «No sabe».
A40: A10 | B40: Animal | C40: Castrado/a | D40: Sí | E40: Castrado/a: Sí / No / No Sabe | F40: No | G40: — | J40: =OR(D40="Sí",D40="Parcial",D40="Implícito")*1+OR(F40="Sí",F40="Parcial",F40="Implícito")*1+OR(H40="Sí",H40="Parcial",H40="Implícito")*1 -> 1 | L40: Solo F1.
A41: A11 | B41: Animal | C41: ¿Puede identificar al animal? | D41: Sí | E41: ¿Podría identificar al animal agresor?: Sí / No | F41: Sí | G41: Puede identificar al ADC: SI / NO / NO SÉ | J41: =OR(D41="Sí",D41="Parcial",D41="Implícito")*1+OR(F41="Sí",F41="Parcial",F41="Implícito")*1+OR(H41="Sí",H41="Parcial",H41="Implícito")*1 -> 2 | L41: F2 agrega «NO SÉ».
...

Sheet Resumen
A1: Resumen de cobertura
A2: Se recalcula solo a partir de la hoja Matriz. «Presente» = Sí, Parcial o Implícito.
A4: 1. Campos presentes por bloque
A5: Bloque | B5: Campos en la matriz | C5: F1 | D5: F2 | E5: F3
A6: Persona | B6: =COUNTIF(Matriz!$B$6:$B$200,$A6) -> 9 | C6: =COUNTIFS(Matriz!$B$6:$B$200,$A6,Matriz!$D$6:$D$200,"Sí")+COUNTIFS(Matriz!$B$6:$B$200,$A6,Matriz!$D$6:$D$200,"Parcial")+COUNTIFS(Matriz!$B$6:$B$200,$A6,Matriz!$D$6:$D$200,"Implícito") -> 5 | D6: =COUNTIFS(Matriz!$B$6:$B$200,$A6,Matriz!$F$6:$F$200,"Sí")+COUNTIFS(Matriz!$B$6:$B$200,$A6,Matriz!$F$6:$F$200,"Parcial")+COUNTIFS(Matriz!$B$6:$B$200,$A6,Matriz!$F$6:$F$200,"Implícito") -> 7 | E6: =COUNTIFS(Matriz!$B$6:$B$200,$A6,Matriz!$H$6:$H$200,"Sí")+COUNTIFS(Matriz!$B$6:$B$200,$A6,Matriz!$H$6:$H$200,"Parcial")+COUNTIFS(Matriz!$B$6:$B$200,$A6,Matriz!$H$6:$H$200,"Implícito") -> 0
A7: Hecho | B7: =COUNTIF(Matriz!$B$6:$B$200,$A7) -> 12 | C7: =COUNTIFS(Matriz!$B$6:$B$200,$A7,Matriz!$D$6:$D$200,"Sí")+COUNTIFS(Matriz!$B$6:$B$200,$A7,Matriz!$D$6:$D$200,"Parcial")+COUNTIFS(Matriz!$B$6:$B$200,$A7,Matriz!$D$6:$D$200,"Implícito") -> 10 | D7: =COUNTIFS(Matriz!$B$6:$B$200,$A7,Matriz!$F$6:$F$200,"Sí")+COUNTIFS(Matriz!$B$6:$B$200,$A7,Matriz!$F$6:$F$200,"Parcial")+COUNTIFS(Matriz!$B$6:$B$200,$A7,Matriz!$F$6:$F$200,"Implícito") -> 9 | E7: =COUNTIFS(Matriz!$B$6:$B$200,$A7,Matriz!$H$6:$H$200,"Sí")+COUNTIFS(Matriz!$B$6:$B$200,$A7,Matriz!$H$6:$H$200,"Parcial")+COUNTIFS(Matriz!$B$6:$B$200,$A7,Matriz!$H$6:$H$200,"Implícito") -> 0
A8: Tipo de evento | B8: =COUNTIF(Matriz!$B$6:$B$200,$A8) -> 1 | C8: =COUNTIFS(Matriz!$B$6:$B$200,$A8,Matriz!$D$6:$D$200,"Sí")+COUNTIFS(Matriz!$B$6:$B$200,$A8,Matriz!$D$6:$D$200,"Parcial")+COUNTIFS(Matriz!$B$6:$B$200,$A8,Matriz!$D$6:$D$200,"Implícito") -> 0 | D8: =COUNTIFS(Matriz!$B$6:$B$200,$A8,Matriz!$F$6:$F$200,"Sí")+COUNTIFS(Matriz!$B$6:$B$200,$A8,Matriz!$F$6:$F$200,"Parcial")+COUNTIFS(Matriz!$B$6:$B$200,$A8,Matriz!$F$6:$F$200,"Implícito") -> 1 | E8: =COUNTIFS(Matriz!$B$6:$B$200,$A8,Matriz!$H$6:$H$200,"Sí")+COUNTIFS(Matriz!$B$6:$B$200,$A8,Matriz!$H$6:$H$200,"Parcial")+COUNTIFS(Matriz!$B$6:$B$200,$A8,Matriz!$H$6:$H$200,"Implícito") -> 0
A9: Documentación y trámite | B9: =COUNTIF(Matriz!$B$6:$B$200,$A9) -> 3 | C9: =COUNTIFS(Matriz!$B$6:$B$200,$A9,Matriz!$D$6:$D$200,"Sí")+COUNTIFS(Matriz!$B$6:$B$200,$A9,Matriz!$D$6:$D$200,"Parcial")+COUNTIFS(Matriz!$B$6:$B$200,$A9,Matriz!$D$6:$D$200,"Implícito") -> 0 | D9: =COUNTIFS(Matriz!$B$6:$B$200,$A9,Matriz!$F$6:$F$200,"Sí")+COUNTIFS(Matriz!$B$6:$B$200,$A9,Matriz!$F$6:$F$200,"Parcial")+COUNTIFS(Matriz!$B$6:$B$200,$A9,Matriz!$F$6:$F$200,"Implícito") -> 3 | E9: =COUNTIFS(Matriz!$B$6:$B$200,$A9,Matriz!$H$6:$H$200,"Sí")+COUNTIFS(Matriz!$B$6:$B$200,$A9,Matriz!$H$6:$H$200,"Parcial")+COUNTIFS(Matriz!$B$6:$B$200,$A9,Matriz!$H$6:$H$200,"Implícito") -> 0
A10: Animal | B10: =COUNTIF(Matriz!$B$6:$B$200,$A10) -> 13 | C10: =COUNTIFS(Matriz!$B$6:$B$200,$A10,Matriz!$D$6:$D$200,"Sí")+COUNTIFS(Matriz!$B$6:$B$200,$A10,Matriz!$D$6:$D$200,"Parcial")+COUNTIFS(Matriz!$B$6:$B$200,$A10,Matriz!$D$6:$D$200,"Implícito") -> 12 | D10: =COUNTIFS(Matriz!$B$6:$B$200,$A10,Matriz!$F$6:$F$200,"Sí")+COUNTIFS(Matriz!$B$6:$B$200,$A10,Matriz!$F$6:$F$200,"Parcial")+COUNTIFS(Matriz!$B$6:$B$200,$A10,Matriz!$F$6:$F$200,"Implícito") -> 10 | E10: =COUNTIFS(Matriz!$B$6:$B$200,$A10,Matriz!$H$6:$H$200,"Sí")+COUNTIFS(Matriz!$B$6:$B$200,$A10,Matriz!$H$6:$H$200,"Parcial")+COUNTIFS(Matriz!$B$6:$B$200,$A10,Matriz!$H$6:$H$200,"Implícito") -> 0
A11: Lesión y atención | B11: =COUNTIF(Matriz!$B$6:$B$200,$A11) -> 7 | C11: =COUNTIFS(Matriz!$B$6:$B$200,$A11,Matriz!$D$6:$D$200,"Sí")+COUNTIFS(Matriz!$B$6:$B$200,$A11,Matriz!$D$6:$D$200,"Parcial")+COUNTIFS(Matriz!$B$6:$B$200,$A11,Matriz!$D$6:$D$200,"Implícito") -> 7 | D11: =COUNTIFS(Matriz!$B$6:$B$200,$A11,Matriz!$F$6:$F$200,"Sí")+COUNTIFS(Matriz!$B$6:$B$200,$A11,Matriz!$F$6:$F$200,"Parcial")+COUNTIFS(Matriz!$B$6:$B$200,$A11,Matriz!$F$6:$F$200,"Implícito") -> 2 | E11: =COUNTIFS(Matriz!$B$6:$B$200,$A11,Matriz!$H$6:$H$200,"Sí")+COUNTIFS(Matriz!$B$6:$B$200,$A11,Matriz!$H$6:$H$200,"Parcial")+COUNTIFS(Matriz!$B$6:$B$200,$A11,Matriz!$H$6:$H$200,"Implícito") -> 0
A12: Denuncia y seguimiento | B12: =COUNTIF(Matriz!$B$6:$B$200,$A12) -> 5 | C12: =COUNTIFS(Matriz!$B$6:$B$200,$A12,Matriz!$D$6:$D$200,"Sí")+COUNTIFS(Matriz!$B$6:$B$200,$A12,Matriz!$D$6:$D$200,"Parcial")+COUNTIFS(Matriz!$B$6:$B$200,$A12,Matriz!$D$6:$D$200,"Implícito") -> 5 | D12: =COUNTIFS(Matriz!$B$6:$B$200,$A12,Matriz!$F$6:$F$200,"Sí")+COUNTIFS(Matriz!$B$6:$B$200,$A12,Matriz!$F$6:$F$200,"Parcial")+COUNTIFS(Matriz!$B$6:$B$200,$A12,Matriz!$F$6:$F$200,"Implícito") -> 2 | E12: =COUNTIFS(Matriz!$B$6:$B$200,$A12,Matriz!$H$6:$H$200,"Sí")+COUNTIFS(Matriz!$B$6:$B$200,$A12,Matriz!$H$6:$H$200,"Parcial")+COUNTIFS(Matriz!$B$6:$B$200,$A12,Matriz!$H$6:$H$200,"Implícito") -> 0
A13: Total | B13: =SUM(B6:B12) -> 50 | C13: =SUM(C6:C12) -> 39 | D13: =SUM(D6:D12) -> 34 | E13: =SUM(E6:E12) -> 0
A15: 2. Cruce F1 vs F2
A16: Situación | B16: Campos
A17: En F1 y F2 | B17: =SUMPRODUCT(((Matriz!$D$6:$D$200="Sí")+(Matriz!$D$6:$D$200="Parcial")+(Matriz!$D$6:$D$200="Implícito"))*((Matriz!$F$6:$F$200="Sí")+(Matriz!$F$6:$F$200="Parcial")+(Matriz!$F$6:$F$200="Implícito"))) -> 23
A18: Solo en F1 | B18: =SUMPRODUCT(((Matriz!$D$6:$D$200="Sí")+(Matriz!$D$6:$D$200="Parcial")+(Matriz!$D$6:$D$200="Implícito"))*(Matriz!$F$6:$F$200="No")) -> 16
A19: Solo en F2 | B19: =SUMPRODUCT((Matriz!$D$6:$D$200="No")*((Matriz!$F$6:$F$200="Sí")+(Matriz!$F$6:$F$200="Parcial")+(Matriz!$F$6:$F$200="Implícito"))) -> 11
A20: Iguales en ambos (Sí / Sí) | B20: =SUMPRODUCT((Matriz!$D$6:$D$200="Sí")*(Matriz!$F$6:$F$200="Sí")) -> 18
A21: «Iguales» = Sí en ambos; puede haber diferencias de opciones (ver columna de notas en Matriz).
A23: 3. Campos pedidos en la Entrevista 1 · ¿qué formulario los tiene?
A24: Fuente: «SIRAM - Estado tras Entrevista 1» (03/09/2026). Los mapeos marcados como inferidos hay que validarlos.
A25: Dato pedido | B25: Para qué | C25: Cód. | D25: F1 | E25: F2 | F25: F3
A26: Cuándo (fecha) | B26: Obligatorio | C26: H1 | D26: =IFERROR(IF(INDEX(Matriz!$D$6:$D$200,MATCH($C26,Matriz!$A$6:$A$200,0))="","",INDEX(Matriz!$D$6:$D$200,MATCH($C26,Matriz!$A$6:$A$200,0))),"") -> Sí | E26: =IFERROR(IF(INDEX(Matriz!$F$6:$F$200,MATCH($C26,Matriz!$A$6:$A$200,0))="","",INDEX(Matriz!$F$6:$F$200,MATCH($C26,Matriz!$A$6:$A$200,0))),"") -> Sí | F26: =IFERROR(IF(INDEX(Matriz!$H$6:$H$200,MATCH($C26,Matriz!$A$6:$A$200,0))="","",INDEX(Matriz!$H$6:$H$200,MATCH($C26,Matriz!$A$6:$A$200,0))),"")
A27: Dónde (ciudad) | B27: Obligatorio | C27: H3 | D27: =IFERROR(IF(INDEX(Matriz!$D$6:$D$200,MATCH($C27,Matriz!$A$6:$A$200,0))="","",INDEX(Matriz!$D$6:$D$200,MATCH($C27,Matriz!$A$6:$A$200,0))),"") -> Sí | E27: =IFERROR(IF(INDEX(Matriz!$F$6:$F$200,MATCH($C27,Matriz!$A$6:$A$200,0))="","",INDEX(Matriz!$F$6:$F$200,MATCH($C27,Matriz!$A$6:$A$200,0))),"") -> Implícito | F27: =IFERROR(IF(INDEX(Matriz!$H$6:$H$200,MATCH($C27,Matriz!$A$6:$A$200,0))="","",INDEX(Matriz!$H$6:$H$200,MATCH($C27,Matriz!$A$6:$A$200,0))),"")
A28: Dónde (lugar) | B28: Obligatorio | C28: H4 | D28: =IFERROR(IF(INDEX(Matriz!$D$6:$D$200,MATCH($C28,Matriz!$A$6:$A$200,0))="","",INDEX(Matriz!$D$6:$D$200,MATCH($C28,Matriz!$A$6:$A$200,0))),"") -> Sí | E28: =IFERROR(IF(INDEX(Matriz!$F$6:$F$200,MATCH($C28,Matriz!$A$6:$A$200,0))="","",INDEX(Matriz!$F$6:$F$200,MATCH($C28,Matriz!$A$6:$A$200,0))),"") -> Sí | F28: =IFERROR(IF(INDEX(Matriz!$H$6:$H$200,MATCH($C28,Matriz!$A$6:$A$200,0))="","",INDEX(Matriz!$H$6:$H$200,MATCH($C28,Matriz!$A$6:$A$200,0))),"")
A29: Situación de la persona → con quién estaba (mapeo inferido) | B29: Obligatorio | C29: H6 | D29: =IFERROR(IF(INDEX(Matriz!$D$6:$D$200,MATCH($C29,Matriz!$A$6:$A$200,0))="","",INDEX(Matriz!$D$6:$D$200,MATCH($C29,Matriz!$A$6:$A$200,0))),"") -> Sí | E29: =IFERROR(IF(INDEX(Matriz!$F$6:$F$200,MATCH($C29,Matriz!$A$6:$A$200,0))="","",INDEX(Matriz!$F$6:$F$200,MATCH($C29,Matriz!$A$6:$A$200,0))),"") -> Sí | F29: =IFERROR(IF(INDEX(Matriz!$H$6:$H$200,MATCH($C29,Matriz!$A$6:$A$200,0))="","",INDEX(Matriz!$H$6:$H$200,MATCH($C29,Matriz!$A$6:$A$200,0))),"")
A30: Situación de la persona → actividad (mapeo inferido) | B30: Obligatorio | C30: H8 | D30: =IFERROR(IF(INDEX(Matriz!$D$6:$D$200,MATCH($C30,Matriz!$A$6:$A$200,0))="","",INDEX(Matriz!$D$6:$D$200,MATCH($C30,Matriz!$A$6:$A$200,0))),"") -> Sí | E30: =IFERROR(IF(INDEX(Matriz!$F$6:$F$200,MATCH($C30,Matriz!$A$6:$A$200,0))="","",INDEX(Matriz!$F$6:$F$200,MATCH($C30,Matriz!$A$6:$A$200,0))),"") -> No | F30: =IFERROR(IF(INDEX(Matriz!$H$6:$H$200,MATCH($C30,Matriz!$A$6:$A$200,0))="","",INDEX(Matriz!$H$6:$H$200,MATCH($C30,Matriz!$A$6:$A$200,0))),"")
A31: Propio / ajeno | B31: Obligatorio | C31: A5 | D31: =IFERROR(IF(INDEX(Matriz!$D$6:$D$200,MATCH($C31,Matriz!$A$6:$A$200,0))="","",INDEX(Matriz!$D$6:$D$200,MATCH($C31,Matriz!$A$6:$A$200,0))),"") -> Sí | E31: =IFERROR(IF(INDEX(Matriz!$F$6:$F$200,MATCH($C31,Matriz!$A$6:$A$200,0))="","",INDEX(Matriz!$F$6:$F$200,MATCH($C31,Matriz!$A$6:$A$200,0))),"") -> Sí | F31: =IFERROR(IF(INDEX(Matriz!$H$6:$H$200,MATCH($C31,Matriz!$A$6:$A$200,0))="","",INDEX(Matriz!$H$6:$H$200,MATCH($C31,Matriz!$A$6:$A$200,0))),"")
A32: Edad | B32: Epidemiológico | C32: P2 | D32: =IFERROR(IF(INDEX(Matriz!$D$6:$D$200,MATCH($C32,Matriz!$A$6:$A$200,0))="","",INDEX(Matriz!$D$6:$D$200,MATCH($C32,Matriz!$A$6:$A$200,0))),"") -> Sí | E32: =IFERROR(IF(INDEX(Matriz!$F$6:$F$200,MATCH($C32,Matriz!$A$6:$A$200,0))="","",INDEX(Matriz!$F$6:$F$200,MATCH($C32,Matriz!$A$6:$A$200,0))),"") -> Sí | F32: =IFERROR(IF(INDEX(Matriz!$H$6:$H$200,MATCH($C32,Matriz!$A$6:$A$200,0))="","",INDEX(Matriz!$H$6:$H$200,MATCH($C32,Matriz!$A$6:$A$200,0))),"")
A33: Zona corporal | B33: Epidemiológico | C33: L3 | D33: =IFERROR(IF(INDEX(Matriz!$D$6:$D$200,MATCH($C33,Matriz!$A$6:$A$200,0))="","",INDEX(Matriz!$D$6:$D$200,MATCH($C33,Matriz!$A$6:$A$200,0))),"") -> Sí | E33: =IFERROR(IF(INDEX(Matriz!$F$6:$F$200,MATCH($C33,Matriz!$A$6:$A$200,0))="","",INDEX(Matriz!$F$6:$F$200,MATCH($C33,Matriz!$A$6:$A$200,0))),"") -> No | F33: =IFERROR(IF(INDEX(Matriz!$H$6:$H$200,MATCH($C33,Matriz!$A$6:$A$200,0))="","",INDEX(Matriz!$H$6:$H$200,MATCH($C33,Matriz!$A$6:$A$200,0))),"")
A34: Ámbito → tipo de lugar (mapeo inferido) | B34: Epidemiológico | C34: H5 | D34: =IFERROR(IF(INDEX(Matriz!$D$6:$D$200,MATCH($C34,Matriz!$A$6:$A$200,0))="","",INDEX(Matriz!$D$6:$D$200,MATCH($C34,Matriz!$A$6:$A$200,0))),"") -> Sí | E34: =IFERROR(IF(INDEX(Matriz!$F$6:$F$200,MATCH($C34,Matriz!$A$6:$A$200,0))="","",INDEX(Matriz!$F$6:$F$200,MATCH($C34,Matriz!$A$6:$A$200,0))),"") -> Sí | F34: =IFERROR(IF(INDEX(Matriz!$H$6:$H$200,MATCH($C34,Matriz!$A$6:$A$200,0))="","",INDEX(Matriz!$H$6:$H$200,MATCH($C34,Matriz!$A$6:$A$200,0))),"")
A35: DNI | B35: Duplicados: clave principal | C35: P6 | D35: =IFERROR(IF(INDEX(Matriz!$D$6:$D$200,MATCH($C35,Matriz!$A$6:$A$200,0))="","",INDEX(Matriz!$D$6:$D$200,MATCH($C35,Matriz!$A$6:$A$200,0))),"") -> No | E35: =IFERROR(IF(INDEX(Matriz!$F$6:$F$200,MATCH($C35,Matriz!$A$6:$A$200,0))="","",INDEX(Matriz!$F$6:$F$200,MATCH($C35,Matriz!$A$6:$A$200,0))),"") -> Sí | F35: =IFERROR(IF(INDEX(Matriz!$H$6:$H$200,MATCH($C35,Matriz!$A$6:$A$200,0))="","",INDEX(Matriz!$H$6:$H$200,MATCH($C35,Matriz!$A$6:$A$200,0))),"")
A36: Correo | B36: Duplicados: complemento | C36: P3 | D36: =IFERROR(IF(INDEX(Matriz!$D$6:$D$200,MATCH($C36,Matriz!$A$6:$A$200,0))="","",INDEX(Matriz!$D$6:$D$200,MATCH($C36,Matriz!$A$6:$A$200,0))),"") -> Sí | E36: =IFERROR(IF(INDEX(Matriz!$F$6:$F$200,MATCH($C36,Matriz!$A$6:$A$200,0))="","",INDEX(Matriz!$F$6:$F$200,MATCH($C36,Matriz!$A$6:$A$200,0))),"") -> No | F36: =IFERROR(IF(INDEX(Matriz!$H$6:$H$200,MATCH($C36,Matriz!$A$6:$A$200,0))="","",INDEX(Matriz!$H$6:$H$200,MATCH($C36,Matriz!$A$6:$A$200,0))),"")
A37: Celular | B37: Duplicados: complemento | C37: P4 | D37: =IFERROR(IF(INDEX(Matriz!$D$6:$D$200,MATCH($C37,Matriz!$A$6:$A$200,0))="","",INDEX(Matriz!$D$6:$D$200,MATCH($C37,Matriz!$A$6:$A$200,0))),"") -> Sí | E37: =IFERROR(IF(INDEX(Matriz!$F$6:$F$200,MATCH($C37,Matriz!$A$6:$A$200,0))="","",INDEX(Matriz!$F$6:$F$200,MATCH($C37,Matriz!$A$6:$A$200,0))),"") -> Sí | F37: =IFERROR(IF(INDEX(Matriz!$H$6:$H$200,MATCH($C37,Matriz!$A$6:$A$200,0))="","",INDEX(Matriz!$H$6:$H$200,MATCH($C37,Matriz!$A$6:$A$200,0))),"")
... A43: Fotos | B43: RF.25 | C43: X2 | D43: =IFERROR(IF(INDEX(Matriz!$D$6:$D$200,MATCH($C43,Matriz!$A$6:$A$200,0))="","",INDEX(Matriz!$D$6:$D$200,MATCH($C43,Matriz!$A$6:$A$200,0))),"") -> No | E43: =IFERROR(IF(INDEX(Matriz!$F$6:$F$200,MATCH($C43,Matriz!$A$6:$A$200,0))="","",INDEX(Matriz!$F$6:$F$200,MATCH($C43,Matriz!$A$6:$A$200,0))),"") -> Sí | F43: =IFERROR(IF(INDEX(Matriz!$H$6:$H$200,MATCH($C43,Matriz!$A$6:$A$200,0))="","",INDEX(Matriz!$H$6:$H$200,MATCH($C43,Matriz!$A$6:$A$200,0))),"")

Sheet Hallazgos
A1: Hallazgos y pendientes
A2: Evidencia: Confirmado (formularios) = surge del texto de los formularios · Confirmado (Entrevista 1) = surge de la entrevista · Inferido = deducción del grupo, a validar · Pendiente = no hay información.
A4: ID | B4: Hallazgo | C4: Campos | D4: Evidencia | E4: Impacto en SIRAM | F4: Siguiente acción / pregunta
A5: HZ01 | B5: El formulario público (F1) no pide DNI; Zoonosis (F2) sí. | C5: P6 | D5: Confirmado (formularios). DNI = clave principal de duplicados según la Entrevista 1. | E5: Los casos del F1 solo se pueden vincular con los del F2 por correo, teléfono y fecha (claves complementarias): más posibles duplicados sin resolver. | F5: Proponer a Adrián agregar DNI al formulario público.
A6: HZ02 | B6: Zoonosis (F2) no registra zona del cuerpo, gravedad ni atención médica. | C6: L2, L3, L4–L7 | D6: Confirmado (formularios). Zona corporal = variable epidemiológica (Entrevista 1). Que esos datos estén en el certificado médico adjunto es inferido. | E6: Los casos que entren solo por Zoonosis quedarán incompletos en zona corporal (semáforo). | F6: Entrevista 2 (Zoonosis): ¿transcriben algún dato del certificado médico? ¿Dónde?
A7: HZ03 | B7: El F2 registra tipos de denuncia que la Entrevista 1 dejó fuera de alcance. | C7: T1 | D7: Confirmado (formulario + Entrevista 1): «Canes sueltos, agresivos» y «Ataque de ADC a otro ADC» quedan fuera. «Mal estado de ADC» no se trató: pendiente. | E7: El importador de Zoonosis debe filtrar por Tipo de denuncia y no traer esos registros. | F7: Confirmar qué hacer con «Mal estado de ADC» y «Otros».
A8: HZ04 | B8: Ninguno de los dos formularios tiene opción explícita para «ataque sin lesión» ni «lesión derivada» (p. ej. caída), que la Entrevista 1 confirmó como registrables. | C8: L1, T1 | D8: Confirmado (formularios + Entrevista 1). | E8: Esos casos llegarían como «Otros» en texto libre; la tipificación (RF.19) necesitará revisión manual. | F8: Proponer agregar esas opciones al formulario público; preguntar a Zoonosis cómo los registra hoy.
A9: HZ05 | B9: Arañazo (F1) vs «Lesión compatible» (F2): categorías distintas. | C9: L1, T1 | D9: Confirmado (formularios). Según la Entrevista 1 el arañazo es lesión compatible, así que F1 Arañazo → Lesión compatible (equivalencia inferida). | E9: Hace falta una tabla de equivalencias en la normalización. | F9: Validar la equivalencia con Adrián.
A10: HZ06 | B10: Ambos formularios incluyen gatos. | C10: A1 | D10: Confirmado (formularios). Gatos dentro del alcance: sin definir (Entrevista 1). | E10: Si quedan fuera, el importador descarta o marca esos registros. | F10: Definir con Adrián.
A11: HZ07 | B11: El F2 distingue denunciante y lesionado; el F1 asume que responde la persona agredida. | C11: P1–P9 | D11: Confirmado (F2). Inferido (F1). | E11: El modelo tiene que separar persona lesionada y denunciante, al menos para la fuente Zoonosis. | F11: Definir si SIRAM guarda los datos del denunciante o solo los del lesionado.
A12: HZ08 | B12: Plazo de 48 h hábiles para presentar el certificado médico; si no, la denuncia se desglosa y se devuelve. | C12: X1, X3 | D12: Confirmado (texto del F2). | E12: Una denuncia puede estar incompleta a la espera del certificado (encaja con el semáforo). Entrevista 1: en SIRAM no se dan de baja denuncias → definir cómo se refleja una denuncia desglosada. | F12: Entrevista 2 (Zoonosis): ¿qué pasa con una denuncia desglosada? ¿Queda registrada?
A13: HZ09 | B13: Escalas de respuesta distintas: «No sé» en unos campos y no en otros; «Chico» vs «Pequeño»; «Solo/Acompañado» vs «Padre/Madre/Amigos/Otros». | C13: A2, A3, A9, A11, A12, H6 | D13: Confirmado (formularios). | E13: La estructura común necesita un valor «desconocido» y tablas de equivalencia. H6: F2 → F1 se puede mapear; F1 → F2 no. | F13: Definir los valores normalizados de cada campo.
A14: HZ10 | B14: «Color del animal» solo está en el F2, pero la Entrevista 1 lo pidió como filtro del mapa. | C14: A13 | D14: Confirmado (formularios + Entrevista 1). | E14: El filtro por color no va a funcionar para casos del F1. | F14: Proponer agregar color al formulario público.
A15: HZ11 | B15: «Situación de la persona» es obligatoria según la Entrevista 1, pero no está definida. F1 tiene con quién estaba y qué hacía; F2 solo con quién estaba. | C15: H6, H8, H9 | D15: Pendiente (definición). El mapeo a H6/H8 es inferido. | E15: Si «situación» = actividad, todos los casos de Zoonosis quedan incompletos en un campo obligatorio. | F15: Definir qué significa «situación de la persona».
... A20: HZ16 | B20: «Conoce al propietario/a del domicilio» es ambiguo. | C20: H11 | D20: Pendiente. | E20: No se puede normalizar sin saber si se refiere al domicilio del hecho o al del animal. | F20: Preguntar a Zoonosis.

Sheet Formularios
A1: Ficha de cada formulario
A3: Atributo | B3: F1 · Formulario público (Schiavini) | C3: F2 · Ventanilla Zoonosis Ushuaia | D3: F3 · (pendiente)
A4: Nombre | B4: Formulario público (Schiavini) | C4: Formulario de denuncia de ADC (O.M. 4800)
A5: Organismo / responsable | B5: Schiavini (según el grupo) | C5: Municipalidad de Ushuaia – Dirección Municipal de Zoonosis
A6: Medio | B6: Formulario online (inferido: Google Forms, por el texto «Tu respuesta») | C6: Papel, en ventanilla
A7: Quién lo completa | B7: La persona agredida (inferido) | C7: El denunciante (puede no ser el lesionado)
A8: Origen del dato en SIRAM | B8: Carga ciudadana, a verificar contra registros de organismos (Entrevista 1; asignación inferida) | C8: Organismo (Zoonosis Ushuaia)
A9: Especies | B9: Perro, gato | C9: Perro, gato (ADC = Animal Doméstico de Compañía)
A10: Ciudades | B10: Río Grande, Tolhuin, Ushuaia, Otros | C10: Ushuaia
A11: Base normativa | B11: No indicada | C11: Ordenanza Municipal 4800
A12: Campos obligatorios | B12: Solo «Ciudad» (*) | C12: No indicados (papel)
A13: Material recibido | B13: Texto de las preguntas, pegado en el chat (22/09/2026) | C13: PDF «denuciasVentanilla.pdf», 2 páginas (22/09/2026)
A14: Relación con la Entrevista 1 | B14: Probablemente es el «formulario 2025» que Adrián iba a compartir con permiso de editor (inferido; confirmar) | C14: Fuente Zoonosis Ushuaia; contacto pendiente vía Adrián
A15: Notas | B15: Bloque «Lesión» → «Comentarios» repetido (HZ13) | C15: Adjuntos: certificado médico, denuncia policial, fotos. Plazo de 48 h hábiles para el certificado (Vito Dumas 220, lunes a viernes de 7 a 19 h).
A16: Campos presentes en la matriz (calculado) | B16: =COUNTIF(Matriz!$D$6:$D$200,"Sí")+COUNTIF(Matriz!$D$6:$D$200,"Parcial")+COUNTIF(Matriz!$D$6:$D$200,"Implícito") -> 39 | C16: =COUNTIF(Matriz!$F$6:$F$200,"Sí")+COUNTIF(Matriz!$F$6:$F$200,"Parcial")+COUNTIF(Matriz!$F$6:$F$200,"Implícito") -> 34 | D16: =COUNTIF(Matriz!$H$6:$H$200,"Sí")+COUNTIF(Matriz!$H$6:$H$200,"Parcial")+COUNTIF(Matriz!$H$6:$H$200,"Implícito") -> 0

Sheet Leyenda
A1: Cómo leer y completar la planilla
A3: Estados
A4: Sí | B4: El formulario pregunta el dato.
A5: Parcial | B5: Lo pregunta de forma incompleta o indirecta (p. ej. solo si adjunta un documento).
A6: Implícito | B6: No lo pregunta, pero el dato se deduce del propio formulario (p. ej. la ciudad del encabezado).
A7: No | B7: El formulario no tiene el dato.
A8: (vacío) | B8: Formulario todavía no cargado.
A10: Bloques y códigos
A11: P | B11: Persona (denunciante / lesionado)
A12: H | B12: Hecho (cuándo, dónde, situación)
A13: T | B13: Tipo de evento
A14: X | B14: Documentación y trámite
A15: A | B15: Animal
A16: L | B16: Lesión y atención médica
A17: D | B17: Denuncia y seguimiento
A19: Cuando llegue el F3
A20: 1 | B20: En la hoja Matriz, completar las columnas amarillas del F3 (Estado + Pregunta y opciones) en cada fila.
A21: 2 | B21: Si el F3 tiene un campo que no está en la matriz, agregarlo en la primera fila libre al final (hay fórmulas preparadas hasta la fila 200), con su bloque y el código siguiente (p. ej. P10), y marcar F1 y F2 como «No».
A22: 3 | B22: Completar la columna F3 de la hoja Formularios.
A23: 4 | B23: Resumen y la columna «Presente en» se recalculan solos. Para ordenar por bloque, usar el filtro de la Matriz.
A25: Ejemplo de carga (ilustrativo, no es un dato real)
A26: Fila | B26: P6 · DNI
A27: F3 · Estado | B27: Sí
A28: F3 · Pregunta y opciones | B28: Documento del paciente (texto)
A30: Fuentes
A31: F1 | B31: Preguntas del formulario público, pegadas en el chat el 22/09/2026.
A32: F2 | B32: PDF «denuciasVentanilla.pdf» (Municipalidad de Ushuaia, Dirección Municipal de Zoonosis), recibido el 22/09/2026.
A33: Entrevista 1 | B33: «SIRAM - Estado tras Entrevista 1 (03-09-2026)», documento del proyecto.
